<?xml version="1.0"?>
<mujoco model="panda">
    <compiler angle="radian" inertiafromgeom="false"/>
    <option timestep="0.01" gravity="0 0 -9.81" integrator="RK4"/>

    <worldbody>
        <body name="panda_link0" pos="0 0 0">
            <geom type="box" size="0.001 0.001 0.001" rgba="0 0 0 0"/>

            <!-- panda_link1 / panda_joint1 -->
            <body name="panda_link1" pos="0 0 0.333">
                <inertial pos="0.003875 0.002081 -0.1750"
                          fullinertia="0.70337 0.70661 0.009117 -0.000139 0.006772 0.019169"
                          mass="4.970684"/>
                <geom type="box" size="0.02 0.02 0.02"/>
                <joint name="panda_joint1" type="hinge" axis="0 0 1"
                       range="-2.8973 2.8973" damping="0" frictionloss="0"/>

                <!-- panda_link2 / panda_joint2 -->
                <body name="panda_link2" pos="0 0 0" quat="0.70710678 -0.70710678 0 0">
                    <inertial pos="-0.003141 -0.02872 0.003495"
                              fullinertia="0.007962 0.02811 0.025995 -0.003925 0.010254 0.000704"
                              mass="0.646926"/>
                    <geom type="box" size="0.02 0.02 0.02"/>
                    <joint name="panda_joint2" type="hinge" axis="0 0 1"
                           range="-1.7628 1.7628" damping="0" frictionloss="0"/>

                    <!-- panda_link3 / panda_joint3 -->
                    <body name="panda_link3" pos="0 -0.316 0" quat="0.70710678 0.70710678 0 0">
                        <inertial pos="0.027518 0.039252 -0.066502"
                                  fullinertia="0.037242 0.036155 0.01083 -0.004761 -0.011396 -0.012805"
                                  mass="3.228604"/>
                        <geom type="box" size="0.02 0.02 0.02"/>
                        <joint name="panda_joint3" type="hinge" axis="0 0 1"
                               range="-2.8973 2.8973" damping="0" frictionloss="0"/>

                        <!-- panda_link4 / panda_joint4 -->
                        <body name="panda_link4" pos="0.0825 0 0" quat="0.70710678 0.70710678 0 0">
                            <inertial pos="-0.05317 0.104419 0.027454"
                                      fullinertia="0.025853 0.019552 0.028323 0.007796 -0.001332 0.008641"
                                      mass="3.587895"/>
                            <geom type="box" size="0.02 0.02 0.02"/>
                            <joint name="panda_joint4" type="hinge" axis="0 0 1"
                                   range="-3.0718 2.0698" damping="0" frictionloss="0"/>

                            <!-- panda_link5 / panda_joint5 -->
                            <body name="panda_link5" pos="-0.0825 0.384 0" quat="0.70710678 -0.70710678 0 0">
                                <inertial pos="-0.011953 0.041065 -0.038437"
                                          fullinertia="0.035549 0.029474 0.008627 -0.002117 -0.004037 0.000229"
                                          mass="1.225946"/>
                                <geom type="box" size="0.02 0.02 0.02"/>
                                <joint name="panda_joint5" type="hinge" axis="0 0 1"
                                       range="-2.8973 2.8973" damping="0" frictionloss="0"/>

                                <!-- panda_link6 / panda_joint6 -->
                                <body name="panda_link6" pos="0 0 0" quat="0.70710678 0.70710678 0 0">
                                    <inertial pos="0.060149 -0.014117 -0.010517"
                                              fullinertia="0.001964 0.004354 0.005433 0.000109 -0.001158 0.000341"
                                              mass="1.666555"/>
                                    <geom type="box" size="0.02 0.02 0.02"/>
                                    <joint name="panda_joint6" type="hinge" axis="0 0 1"
                                           range="-0.0175 3.7525" damping="0" frictionloss="0"/>

                                    <!-- panda_link7 / panda_joint7 -->
                                    <body name="panda_link7" pos="0.088 0 0" quat="0.70710678 0.70710678 0 0">
                                        <inertial pos="0.010517 -0.004252 0.061597"
                                                  fullinertia="0.012516 0.010027 0.004815 -0.000428 -0.001196 -0.000741"
                                                  mass="0.735522"/>
                                        <geom type="box" size="0.02 0.02 0.02"/>
                                        <joint name="panda_joint7" type="hinge" axis="0 0 1"
                                               range="-2.8973 2.8973" damping="0" frictionloss="0"/>

                                        <!-- panda_link8：固定在 link7 上，无 joint -->
                                        <body name="panda_link8" pos="0 0 0.107">
                                            <inertial pos="0 0 0"
                                                      fullinertia="0.001 0.001 0.001 0 0 0"
                                                      mass="0"/>
                                            <geom type="box" size="0.005 0.005 0.005"/>
                                        </body>
                                    </body>
                                </body>
                            </body>
                        </body>
                    </body>
                </body>
            </body>
        </body>
    </worldbody>

    <actuator>
        <general joint="panda_joint1" gear="1" biasprm="0 0 0"/>
        <general joint="panda_joint2" gear="1" biasprm="0 0 0"/>
        <general joint="panda_joint3" gear="1" biasprm="0 0 0"/>
        <general joint="panda_joint4" gear="1" biasprm="0 0 0"/>
        <general joint="panda_joint5" gear="1" biasprm="0 0 0"/>
        <general joint="panda_joint6" gear="1" biasprm="0 0 0"/>
        <general joint="panda_joint7" gear="1" biasprm="0 0 0"/>
    </actuator>
</mujoco>